[28/Feb/2016 13:54:03] DEBUG [django.db.backends:89] (0.000) SET SQL_AUTO_IS_NULL = 0; args=None
[28/Feb/2016 13:54:03] DEBUG [django.db.backends:89] (0.000) SET SQL_AUTO_IS_NULL = 0; args=None
[28/Feb/2016 13:54:03] DEBUG [django.db.backends:89] (0.000) SHOW FULL TABLES; args=None
[28/Feb/2016 13:54:03] DEBUG [django.db.backends:89] (0.000) SELECT `django_migrations`.`app`, `django_migrations`.`name` FROM `django_migrations`; args=()
[28/Feb/2016 13:54:23] WARNING [django.request:170] Not Found: /favicon.ico
[28/Feb/2016 13:55:46] DEBUG [django.db.backends:89] (0.000) SET SQL_AUTO_IS_NULL = 0; args=None
[28/Feb/2016 13:55:46] DEBUG [django.db.backends:89] (0.000) SET SQL_AUTO_IS_NULL = 0; args=None
[28/Feb/2016 13:55:46] DEBUG [django.db.backends:89] (0.000) SHOW FULL TABLES; args=None
[28/Feb/2016 13:55:46] DEBUG [django.db.backends:89] (0.000) SELECT `django_migrations`.`app`, `django_migrations`.`name` FROM `django_migrations`; args=()
[28/Feb/2016 13:58:12] DEBUG [django.db.backends:89] (0.000) SET SQL_AUTO_IS_NULL = 0; args=None
[28/Feb/2016 13:58:12] DEBUG [django.db.backends:89] (0.000) SET SQL_AUTO_IS_NULL = 0; args=None
[28/Feb/2016 13:58:12] DEBUG [django.db.backends:89] (0.000) SHOW FULL TABLES; args=None
[28/Feb/2016 13:58:12] DEBUG [django.db.backends:89] (0.000) SELECT `django_migrations`.`app`, `django_migrations`.`name` FROM `django_migrations`; args=()
[28/Feb/2016 13:58:18] DEBUG [django.db.backends:89] (0.000) SET SQL_AUTO_IS_NULL = 0; args=None
[28/Feb/2016 13:58:18] DEBUG [django.db.backends:89] (0.000) SET SQL_AUTO_IS_NULL = 0; args=None
[28/Feb/2016 13:58:18] DEBUG [django.db.backends:89] (0.000) SHOW FULL TABLES; args=None
[28/Feb/2016 13:58:18] DEBUG [django.db.backends:89] (0.000) SELECT `django_migrations`.`app`, `django_migrations`.`name` FROM `django_migrations`; args=()
[28/Feb/2016 13:58:36] DEBUG [erpsms:34] this is a debug message!
[28/Feb/2016 13:58:57] DEBUG [django.db.backends:89] (0.000) SET SQL_AUTO_IS_NULL = 0; args=None
[28/Feb/2016 13:58:57] DEBUG [django.db.backends:89] (0.000) SET SQL_AUTO_IS_NULL = 0; args=None
[28/Feb/2016 13:58:57] DEBUG [django.db.backends:89] (0.000) SHOW FULL TABLES; args=None
[28/Feb/2016 13:58:57] DEBUG [django.db.backends:89] (0.000) SELECT `django_migrations`.`app`, `django_migrations`.`name` FROM `django_migrations`; args=()
[28/Feb/2016 13:59:12] ERROR [erpsms:34] this is a debug message!
[28/Feb/2016 14:04:55] DEBUG [django.db.backends:89] (0.000) SET SQL_AUTO_IS_NULL = 0; args=None
[28/Feb/2016 14:04:55] DEBUG [django.db.backends:89] (0.000) SET SQL_AUTO_IS_NULL = 0; args=None
[28/Feb/2016 14:04:55] DEBUG [django.db.backends:89] (0.000) SHOW FULL TABLES; args=None
[28/Feb/2016 14:04:55] DEBUG [django.db.backends:89] (0.000) SELECT `django_migrations`.`app`, `django_migrations`.`name` FROM `django_migrations`; args=()
[28/Feb/2016 14:05:08] DEBUG [erpsms:35] this is a debug message!
[28/Feb/2016 14:05:33] DEBUG [django.db.backends:89] (0.000) SET SQL_AUTO_IS_NULL = 0; args=None
[28/Feb/2016 14:05:33] DEBUG [django.db.backends:89] (0.000) SET SQL_AUTO_IS_NULL = 0; args=None
[28/Feb/2016 14:05:33] DEBUG [django.db.backends:89] (0.000) SHOW FULL TABLES; args=None
[28/Feb/2016 14:05:33] DEBUG [django.db.backends:89] (0.000) SELECT `django_migrations`.`app`, `django_migrations`.`name` FROM `django_migrations`; args=()
[28/Feb/2016 14:05:37] DEBUG [django.db.backends:89] (0.000) SET SQL_AUTO_IS_NULL = 0; args=None
[28/Feb/2016 14:05:37] DEBUG [django.db.backends:89] (0.000) SET SQL_AUTO_IS_NULL = 0; args=None
[28/Feb/2016 14:05:37] DEBUG [django.db.backends:89] (0.000) SHOW FULL TABLES; args=None
[28/Feb/2016 14:05:37] DEBUG [django.db.backends:89] (0.000) SELECT `django_migrations`.`app`, `django_migrations`.`name` FROM `django_migrations`; args=()
[28/Feb/2016 14:05:47] DEBUG [django.db.backends:89] (0.000) SET SQL_AUTO_IS_NULL = 0; args=None
[28/Feb/2016 14:05:47] DEBUG [django.db.backends:89] (0.000) SET SQL_AUTO_IS_NULL = 0; args=None
[28/Feb/2016 14:05:47] DEBUG [django.db.backends:89] (0.000) SHOW FULL TABLES; args=None
[28/Feb/2016 14:05:47] DEBUG [django.db.backends:89] (0.000) SELECT `django_migrations`.`app`, `django_migrations`.`name` FROM `django_migrations`; args=()
[04/Mar/2016 18:17:07] DEBUG [django.db.backends:89] (0.004) SET SQL_AUTO_IS_NULL = 0; args=None
[04/Mar/2016 18:17:07] DEBUG [django.db.backends:89] (0.001) SET SQL_AUTO_IS_NULL = 0; args=None
[04/Mar/2016 18:17:07] DEBUG [django.db.backends:89] (0.001) SHOW FULL TABLES; args=None
[04/Mar/2016 18:17:07] DEBUG [django.db.backends:89] (0.003) SELECT `django_migrations`.`app`, `django_migrations`.`name` FROM `django_migrations`; args=()
[04/Mar/2016 18:42:12] ERROR [django.request:256] Internal Server Error: /
Traceback (most recent call last):
  File "/home/erpforppl/erpenv/local/lib/python2.7/site-packages/django/core/handlers/base.py", line 119, in get_response
    resolver_match = resolver.resolve(request.path_info)
  File "/home/erpforppl/erpenv/local/lib/python2.7/site-packages/django/core/urlresolvers.py", line 366, in resolve
    for pattern in self.url_patterns:
  File "/home/erpforppl/erpenv/local/lib/python2.7/site-packages/django/core/urlresolvers.py", line 402, in url_patterns
    patterns = getattr(self.urlconf_module, "urlpatterns", self.urlconf_module)
  File "/home/erpforppl/erpenv/local/lib/python2.7/site-packages/django/core/urlresolvers.py", line 396, in urlconf_module
    self._urlconf_module = import_module(self.urlconf_name)
  File "/usr/lib/python2.7/importlib/__init__.py", line 37, in import_module
    __import__(name)
ImportError: No module named urls
[04/Mar/2016 18:42:40] ERROR [django.request:256] Internal Server Error: /
Traceback (most recent call last):
  File "/home/erpforppl/erpenv/local/lib/python2.7/site-packages/django/core/handlers/base.py", line 119, in get_response
    resolver_match = resolver.resolve(request.path_info)
  File "/home/erpforppl/erpenv/local/lib/python2.7/site-packages/django/core/urlresolvers.py", line 366, in resolve
    for pattern in self.url_patterns:
  File "/home/erpforppl/erpenv/local/lib/python2.7/site-packages/django/core/urlresolvers.py", line 402, in url_patterns
    patterns = getattr(self.urlconf_module, "urlpatterns", self.urlconf_module)
  File "/home/erpforppl/erpenv/local/lib/python2.7/site-packages/django/core/urlresolvers.py", line 396, in urlconf_module
    self._urlconf_module = import_module(self.urlconf_name)
  File "/usr/lib/python2.7/importlib/__init__.py", line 37, in import_module
    __import__(name)
ImportError: No module named urls
[04/Mar/2016 18:44:24] ERROR [django.request:256] Internal Server Error: /
Traceback (most recent call last):
  File "/home/erpforppl/erpenv/local/lib/python2.7/site-packages/django/core/handlers/base.py", line 119, in get_response
    resolver_match = resolver.resolve(request.path_info)
  File "/home/erpforppl/erpenv/local/lib/python2.7/site-packages/django/core/urlresolvers.py", line 366, in resolve
    for pattern in self.url_patterns:
  File "/home/erpforppl/erpenv/local/lib/python2.7/site-packages/django/core/urlresolvers.py", line 402, in url_patterns
    patterns = getattr(self.urlconf_module, "urlpatterns", self.urlconf_module)
  File "/home/erpforppl/erpenv/local/lib/python2.7/site-packages/django/core/urlresolvers.py", line 396, in urlconf_module
    self._urlconf_module = import_module(self.urlconf_name)
  File "/usr/lib/python2.7/importlib/__init__.py", line 37, in import_module
    __import__(name)
ImportError: No module named urls
[04/Mar/2016 18:44:26] ERROR [django.request:256] Internal Server Error: /
Traceback (most recent call last):
  File "/home/erpforppl/erpenv/local/lib/python2.7/site-packages/django/core/handlers/base.py", line 119, in get_response
    resolver_match = resolver.resolve(request.path_info)
  File "/home/erpforppl/erpenv/local/lib/python2.7/site-packages/django/core/urlresolvers.py", line 366, in resolve
    for pattern in self.url_patterns:
  File "/home/erpforppl/erpenv/local/lib/python2.7/site-packages/django/core/urlresolvers.py", line 402, in url_patterns
    patterns = getattr(self.urlconf_module, "urlpatterns", self.urlconf_module)
  File "/home/erpforppl/erpenv/local/lib/python2.7/site-packages/django/core/urlresolvers.py", line 396, in urlconf_module
    self._urlconf_module = import_module(self.urlconf_name)
  File "/usr/lib/python2.7/importlib/__init__.py", line 37, in import_module
    __import__(name)
ImportError: No module named urls
[04/Mar/2016 18:45:30] ERROR [django.request:256] Internal Server Error: /
Traceback (most recent call last):
  File "/home/erpforppl/erpenv/local/lib/python2.7/site-packages/django/core/handlers/base.py", line 119, in get_response
    resolver_match = resolver.resolve(request.path_info)
  File "/home/erpforppl/erpenv/local/lib/python2.7/site-packages/django/core/urlresolvers.py", line 366, in resolve
    for pattern in self.url_patterns:
  File "/home/erpforppl/erpenv/local/lib/python2.7/site-packages/django/core/urlresolvers.py", line 402, in url_patterns
    patterns = getattr(self.urlconf_module, "urlpatterns", self.urlconf_module)
  File "/home/erpforppl/erpenv/local/lib/python2.7/site-packages/django/core/urlresolvers.py", line 396, in urlconf_module
    self._urlconf_module = import_module(self.urlconf_name)
  File "/usr/lib/python2.7/importlib/__init__.py", line 37, in import_module
    __import__(name)
  File "/home/erpforppl/erpsms/erpsms/urls.py", line 28, in <module>
    url(r'', include('social_auth.urls')),
  File "/home/erpforppl/erpenv/local/lib/python2.7/site-packages/django/conf/urls/__init__.py", line 33, in include
    urlconf_module = import_module(urlconf_module)
  File "/usr/lib/python2.7/importlib/__init__.py", line 37, in import_module
    __import__(name)
ImportError: No module named social_auth.urls
[04/Mar/2016 18:45:32] ERROR [django.request:256] Internal Server Error: /
Traceback (most recent call last):
  File "/home/erpforppl/erpenv/local/lib/python2.7/site-packages/django/core/handlers/base.py", line 119, in get_response
    resolver_match = resolver.resolve(request.path_info)
  File "/home/erpforppl/erpenv/local/lib/python2.7/site-packages/django/core/urlresolvers.py", line 366, in resolve
    for pattern in self.url_patterns:
  File "/home/erpforppl/erpenv/local/lib/python2.7/site-packages/django/core/urlresolvers.py", line 402, in url_patterns
    patterns = getattr(self.urlconf_module, "urlpatterns", self.urlconf_module)
  File "/home/erpforppl/erpenv/local/lib/python2.7/site-packages/django/core/urlresolvers.py", line 396, in urlconf_module
    self._urlconf_module = import_module(self.urlconf_name)
  File "/usr/lib/python2.7/importlib/__init__.py", line 37, in import_module
    __import__(name)
  File "/home/erpforppl/erpsms/erpsms/urls.py", line 28, in <module>
    url(r'', include('social_auth.urls')),
  File "/home/erpforppl/erpenv/local/lib/python2.7/site-packages/django/conf/urls/__init__.py", line 33, in include
    urlconf_module = import_module(urlconf_module)
  File "/usr/lib/python2.7/importlib/__init__.py", line 37, in import_module
    __import__(name)
ImportError: No module named social_auth.urls
[04/Mar/2016 18:48:50] ERROR [django.request:256] Internal Server Error: /
Traceback (most recent call last):
  File "/home/erpforppl/erpenv/local/lib/python2.7/site-packages/django/core/handlers/base.py", line 119, in get_response
    resolver_match = resolver.resolve(request.path_info)
  File "/home/erpforppl/erpenv/local/lib/python2.7/site-packages/django/core/urlresolvers.py", line 366, in resolve
    for pattern in self.url_patterns:
  File "/home/erpforppl/erpenv/local/lib/python2.7/site-packages/django/core/urlresolvers.py", line 402, in url_patterns
    patterns = getattr(self.urlconf_module, "urlpatterns", self.urlconf_module)
  File "/home/erpforppl/erpenv/local/lib/python2.7/site-packages/django/core/urlresolvers.py", line 396, in urlconf_module
    self._urlconf_module = import_module(self.urlconf_name)
  File "/usr/lib/python2.7/importlib/__init__.py", line 37, in import_module
    __import__(name)
  File "/home/erpforppl/erpsms/erpsms/urls.py", line 38, in <module>
    urlpatterns += patterns('', url(r'^schools', include('schools.urls')))
  File "/home/erpforppl/erpenv/local/lib/python2.7/site-packages/django/conf/urls/__init__.py", line 33, in include
    urlconf_module = import_module(urlconf_module)
  File "/usr/lib/python2.7/importlib/__init__.py", line 37, in import_module
    __import__(name)
  File "/home/erpforppl/erpsms/schools/urls.py", line 4, in <module>
    from schools.views import *
  File "/home/erpforppl/erpsms/schools/views.py", line 4, in <module>
    from developer_config_file import *
ImportError: No module named developer_config_file
[04/Mar/2016 18:50:07] ERROR [django.request:256] Internal Server Error: /
Traceback (most recent call last):
  File "/home/erpforppl/erpenv/local/lib/python2.7/site-packages/django/core/handlers/base.py", line 119, in get_response
    resolver_match = resolver.resolve(request.path_info)
  File "/home/erpforppl/erpenv/local/lib/python2.7/site-packages/django/core/urlresolvers.py", line 368, in resolve
    sub_match = pattern.resolve(new_path)
  File "/home/erpforppl/erpenv/local/lib/python2.7/site-packages/django/core/urlresolvers.py", line 240, in resolve
    return ResolverMatch(self.callback, args, kwargs, self.name)
  File "/home/erpforppl/erpenv/local/lib/python2.7/site-packages/django/core/urlresolvers.py", line 247, in callback
    self._callback = get_callable(self._callback_str)
  File "/home/erpforppl/erpenv/local/lib/python2.7/site-packages/django/utils/lru_cache.py", line 101, in wrapper
    result = user_function(*args, **kwds)
  File "/home/erpforppl/erpenv/local/lib/python2.7/site-packages/django/core/urlresolvers.py", line 106, in get_callable
    mod = import_module(mod_name)
  File "/usr/lib/python2.7/importlib/__init__.py", line 37, in import_module
    __import__(name)
ImportError: No module named views
[04/Mar/2016 18:51:20] ERROR [django.request:256] Internal Server Error: /
Traceback (most recent call last):
  File "/home/erpforppl/erpenv/local/lib/python2.7/site-packages/django/core/handlers/base.py", line 119, in get_response
    resolver_match = resolver.resolve(request.path_info)
  File "/home/erpforppl/erpenv/local/lib/python2.7/site-packages/django/core/urlresolvers.py", line 368, in resolve
    sub_match = pattern.resolve(new_path)
  File "/home/erpforppl/erpenv/local/lib/python2.7/site-packages/django/core/urlresolvers.py", line 240, in resolve
    return ResolverMatch(self.callback, args, kwargs, self.name)
  File "/home/erpforppl/erpenv/local/lib/python2.7/site-packages/django/core/urlresolvers.py", line 247, in callback
    self._callback = get_callable(self._callback_str)
  File "/home/erpforppl/erpenv/local/lib/python2.7/site-packages/django/utils/lru_cache.py", line 101, in wrapper
    result = user_function(*args, **kwds)
  File "/home/erpforppl/erpenv/local/lib/python2.7/site-packages/django/core/urlresolvers.py", line 106, in get_callable
    mod = import_module(mod_name)
  File "/usr/lib/python2.7/importlib/__init__.py", line 37, in import_module
    __import__(name)
ImportError: No module named views
[04/Mar/2016 18:51:26] ERROR [django.request:256] Internal Server Error: /
Traceback (most recent call last):
  File "/home/erpforppl/erpenv/local/lib/python2.7/site-packages/django/core/handlers/base.py", line 119, in get_response
    resolver_match = resolver.resolve(request.path_info)
  File "/home/erpforppl/erpenv/local/lib/python2.7/site-packages/django/core/urlresolvers.py", line 368, in resolve
    sub_match = pattern.resolve(new_path)
  File "/home/erpforppl/erpenv/local/lib/python2.7/site-packages/django/core/urlresolvers.py", line 240, in resolve
    return ResolverMatch(self.callback, args, kwargs, self.name)
  File "/home/erpforppl/erpenv/local/lib/python2.7/site-packages/django/core/urlresolvers.py", line 247, in callback
    self._callback = get_callable(self._callback_str)
  File "/home/erpforppl/erpenv/local/lib/python2.7/site-packages/django/utils/lru_cache.py", line 101, in wrapper
    result = user_function(*args, **kwds)
  File "/home/erpforppl/erpenv/local/lib/python2.7/site-packages/django/core/urlresolvers.py", line 106, in get_callable
    mod = import_module(mod_name)
  File "/usr/lib/python2.7/importlib/__init__.py", line 37, in import_module
    __import__(name)
ImportError: No module named views
[04/Mar/2016 18:57:09] DEBUG [django.db.backends:89] (0.001) SET SQL_AUTO_IS_NULL = 0; args=None
[04/Mar/2016 18:57:09] DEBUG [django.db.backends:89] (0.001) SET SQL_AUTO_IS_NULL = 0; args=None
[04/Mar/2016 18:57:09] DEBUG [django.db.backends:89] (0.001) SHOW FULL TABLES; args=None
[04/Mar/2016 18:57:09] DEBUG [django.db.backends:89] (0.001) SELECT `django_migrations`.`app`, `django_migrations`.`name` FROM `django_migrations`; args=()
[04/Mar/2016 18:57:13] ERROR [django.request:256] Internal Server Error: /
Traceback (most recent call last):
  File "/home/erpforppl/erpenv/local/lib/python2.7/site-packages/django/core/handlers/base.py", line 119, in get_response
    resolver_match = resolver.resolve(request.path_info)
  File "/home/erpforppl/erpenv/local/lib/python2.7/site-packages/django/core/urlresolvers.py", line 368, in resolve
    sub_match = pattern.resolve(new_path)
  File "/home/erpforppl/erpenv/local/lib/python2.7/site-packages/django/core/urlresolvers.py", line 240, in resolve
    return ResolverMatch(self.callback, args, kwargs, self.name)
  File "/home/erpforppl/erpenv/local/lib/python2.7/site-packages/django/core/urlresolvers.py", line 247, in callback
    self._callback = get_callable(self._callback_str)
  File "/home/erpforppl/erpenv/local/lib/python2.7/site-packages/django/utils/lru_cache.py", line 101, in wrapper
    result = user_function(*args, **kwds)
  File "/home/erpforppl/erpenv/local/lib/python2.7/site-packages/django/core/urlresolvers.py", line 106, in get_callable
    mod = import_module(mod_name)
  File "/usr/lib/python2.7/importlib/__init__.py", line 37, in import_module
    __import__(name)
ImportError: No module named views
[04/Mar/2016 18:57:17] ERROR [django.request:256] Internal Server Error: /
Traceback (most recent call last):
  File "/home/erpforppl/erpenv/local/lib/python2.7/site-packages/django/core/handlers/base.py", line 119, in get_response
    resolver_match = resolver.resolve(request.path_info)
  File "/home/erpforppl/erpenv/local/lib/python2.7/site-packages/django/core/urlresolvers.py", line 368, in resolve
    sub_match = pattern.resolve(new_path)
  File "/home/erpforppl/erpenv/local/lib/python2.7/site-packages/django/core/urlresolvers.py", line 240, in resolve
    return ResolverMatch(self.callback, args, kwargs, self.name)
  File "/home/erpforppl/erpenv/local/lib/python2.7/site-packages/django/core/urlresolvers.py", line 247, in callback
    self._callback = get_callable(self._callback_str)
  File "/home/erpforppl/erpenv/local/lib/python2.7/site-packages/django/utils/lru_cache.py", line 101, in wrapper
    result = user_function(*args, **kwds)
  File "/home/erpforppl/erpenv/local/lib/python2.7/site-packages/django/core/urlresolvers.py", line 106, in get_callable
    mod = import_module(mod_name)
  File "/usr/lib/python2.7/importlib/__init__.py", line 37, in import_module
    __import__(name)
ImportError: No module named views
[04/Mar/2016 18:57:56] ERROR [django.request:256] Internal Server Error: /
Traceback (most recent call last):
  File "/home/erpforppl/erpenv/local/lib/python2.7/site-packages/django/core/handlers/base.py", line 119, in get_response
    resolver_match = resolver.resolve(request.path_info)
  File "/home/erpforppl/erpenv/local/lib/python2.7/site-packages/django/core/urlresolvers.py", line 368, in resolve
    sub_match = pattern.resolve(new_path)
  File "/home/erpforppl/erpenv/local/lib/python2.7/site-packages/django/core/urlresolvers.py", line 240, in resolve
    return ResolverMatch(self.callback, args, kwargs, self.name)
  File "/home/erpforppl/erpenv/local/lib/python2.7/site-packages/django/core/urlresolvers.py", line 247, in callback
    self._callback = get_callable(self._callback_str)
  File "/home/erpforppl/erpenv/local/lib/python2.7/site-packages/django/utils/lru_cache.py", line 101, in wrapper
    result = user_function(*args, **kwds)
  File "/home/erpforppl/erpenv/local/lib/python2.7/site-packages/django/core/urlresolvers.py", line 106, in get_callable
    mod = import_module(mod_name)
  File "/usr/lib/python2.7/importlib/__init__.py", line 37, in import_module
    __import__(name)
ImportError: No module named views
[04/Mar/2016 18:59:26] ERROR [django.request:256] Internal Server Error: /
Traceback (most recent call last):
  File "/home/erpforppl/erpenv/local/lib/python2.7/site-packages/django/core/handlers/base.py", line 119, in get_response
    resolver_match = resolver.resolve(request.path_info)
  File "/home/erpforppl/erpenv/local/lib/python2.7/site-packages/django/core/urlresolvers.py", line 368, in resolve
    sub_match = pattern.resolve(new_path)
  File "/home/erpforppl/erpenv/local/lib/python2.7/site-packages/django/core/urlresolvers.py", line 240, in resolve
    return ResolverMatch(self.callback, args, kwargs, self.name)
  File "/home/erpforppl/erpenv/local/lib/python2.7/site-packages/django/core/urlresolvers.py", line 247, in callback
    self._callback = get_callable(self._callback_str)
  File "/home/erpforppl/erpenv/local/lib/python2.7/site-packages/django/utils/lru_cache.py", line 101, in wrapper
    result = user_function(*args, **kwds)
  File "/home/erpforppl/erpenv/local/lib/python2.7/site-packages/django/core/urlresolvers.py", line 106, in get_callable
    mod = import_module(mod_name)
  File "/usr/lib/python2.7/importlib/__init__.py", line 37, in import_module
    __import__(name)
ImportError: No module named views
[04/Mar/2016 19:03:56] ERROR [django.request:256] Internal Server Error: /
Traceback (most recent call last):
  File "/home/erpforppl/erpenv/local/lib/python2.7/site-packages/django/core/handlers/base.py", line 119, in get_response
    resolver_match = resolver.resolve(request.path_info)
  File "/home/erpforppl/erpenv/local/lib/python2.7/site-packages/django/core/urlresolvers.py", line 368, in resolve
    sub_match = pattern.resolve(new_path)
  File "/home/erpforppl/erpenv/local/lib/python2.7/site-packages/django/core/urlresolvers.py", line 240, in resolve
    return ResolverMatch(self.callback, args, kwargs, self.name)
  File "/home/erpforppl/erpenv/local/lib/python2.7/site-packages/django/core/urlresolvers.py", line 247, in callback
    self._callback = get_callable(self._callback_str)
  File "/home/erpforppl/erpenv/local/lib/python2.7/site-packages/django/utils/lru_cache.py", line 101, in wrapper
    result = user_function(*args, **kwds)
  File "/home/erpforppl/erpenv/local/lib/python2.7/site-packages/django/core/urlresolvers.py", line 106, in get_callable
    mod = import_module(mod_name)
  File "/usr/lib/python2.7/importlib/__init__.py", line 37, in import_module
    __import__(name)
ImportError: No module named views
[04/Mar/2016 19:04:29] ERROR [django.request:256] Internal Server Error: /
Traceback (most recent call last):
  File "/home/erpforppl/erpenv/local/lib/python2.7/site-packages/django/core/handlers/base.py", line 119, in get_response
    resolver_match = resolver.resolve(request.path_info)
  File "/home/erpforppl/erpenv/local/lib/python2.7/site-packages/django/core/urlresolvers.py", line 368, in resolve
    sub_match = pattern.resolve(new_path)
  File "/home/erpforppl/erpenv/local/lib/python2.7/site-packages/django/core/urlresolvers.py", line 240, in resolve
    return ResolverMatch(self.callback, args, kwargs, self.name)
  File "/home/erpforppl/erpenv/local/lib/python2.7/site-packages/django/core/urlresolvers.py", line 247, in callback
    self._callback = get_callable(self._callback_str)
  File "/home/erpforppl/erpenv/local/lib/python2.7/site-packages/django/utils/lru_cache.py", line 101, in wrapper
    result = user_function(*args, **kwds)
  File "/home/erpforppl/erpenv/local/lib/python2.7/site-packages/django/core/urlresolvers.py", line 106, in get_callable
    mod = import_module(mod_name)
  File "/usr/lib/python2.7/importlib/__init__.py", line 37, in import_module
    __import__(name)
ImportError: No module named views
[04/Mar/2016 19:05:26] ERROR [django.request:256] Internal Server Error: /
Traceback (most recent call last):
  File "/home/erpforppl/erpenv/local/lib/python2.7/site-packages/django/core/handlers/base.py", line 119, in get_response
    resolver_match = resolver.resolve(request.path_info)
  File "/home/erpforppl/erpenv/local/lib/python2.7/site-packages/django/core/urlresolvers.py", line 368, in resolve
    sub_match = pattern.resolve(new_path)
  File "/home/erpforppl/erpenv/local/lib/python2.7/site-packages/django/core/urlresolvers.py", line 240, in resolve
    return ResolverMatch(self.callback, args, kwargs, self.name)
  File "/home/erpforppl/erpenv/local/lib/python2.7/site-packages/django/core/urlresolvers.py", line 247, in callback
    self._callback = get_callable(self._callback_str)
  File "/home/erpforppl/erpenv/local/lib/python2.7/site-packages/django/utils/lru_cache.py", line 101, in wrapper
    result = user_function(*args, **kwds)
  File "/home/erpforppl/erpenv/local/lib/python2.7/site-packages/django/core/urlresolvers.py", line 106, in get_callable
    mod = import_module(mod_name)
  File "/usr/lib/python2.7/importlib/__init__.py", line 37, in import_module
    __import__(name)
ImportError: No module named views
[04/Mar/2016 19:06:33] ERROR [django.request:256] Internal Server Error: /
Traceback (most recent call last):
  File "/home/erpforppl/erpenv/local/lib/python2.7/site-packages/django/core/handlers/base.py", line 119, in get_response
    resolver_match = resolver.resolve(request.path_info)
  File "/home/erpforppl/erpenv/local/lib/python2.7/site-packages/django/core/urlresolvers.py", line 368, in resolve
    sub_match = pattern.resolve(new_path)
  File "/home/erpforppl/erpenv/local/lib/python2.7/site-packages/django/core/urlresolvers.py", line 240, in resolve
    return ResolverMatch(self.callback, args, kwargs, self.name)
  File "/home/erpforppl/erpenv/local/lib/python2.7/site-packages/django/core/urlresolvers.py", line 247, in callback
    self._callback = get_callable(self._callback_str)
  File "/home/erpforppl/erpenv/local/lib/python2.7/site-packages/django/utils/lru_cache.py", line 101, in wrapper
    result = user_function(*args, **kwds)
  File "/home/erpforppl/erpenv/local/lib/python2.7/site-packages/django/core/urlresolvers.py", line 106, in get_callable
    mod = import_module(mod_name)
  File "/usr/lib/python2.7/importlib/__init__.py", line 37, in import_module
    __import__(name)
ImportError: No module named views
[04/Mar/2016 19:08:43] ERROR [django.request:256] Internal Server Error: /
Traceback (most recent call last):
  File "/home/erpforppl/erpenv/local/lib/python2.7/site-packages/django/core/handlers/base.py", line 119, in get_response
    resolver_match = resolver.resolve(request.path_info)
  File "/home/erpforppl/erpenv/local/lib/python2.7/site-packages/django/core/urlresolvers.py", line 368, in resolve
    sub_match = pattern.resolve(new_path)
  File "/home/erpforppl/erpenv/local/lib/python2.7/site-packages/django/core/urlresolvers.py", line 240, in resolve
    return ResolverMatch(self.callback, args, kwargs, self.name)
  File "/home/erpforppl/erpenv/local/lib/python2.7/site-packages/django/core/urlresolvers.py", line 247, in callback
    self._callback = get_callable(self._callback_str)
  File "/home/erpforppl/erpenv/local/lib/python2.7/site-packages/django/utils/lru_cache.py", line 101, in wrapper
    result = user_function(*args, **kwds)
  File "/home/erpforppl/erpenv/local/lib/python2.7/site-packages/django/core/urlresolvers.py", line 106, in get_callable
    mod = import_module(mod_name)
  File "/usr/lib/python2.7/importlib/__init__.py", line 37, in import_module
    __import__(name)
ImportError: No module named views
